<?xml version="1.0" encoding="utf-8"?>
<!-- =================================================================================== -->
<!-- |    This document was autogenerated by xacro from human_arm_description.xacro    | -->
<!-- |    EDITING THIS FILE BY HAND IS NOT RECOMMENDED                                 | -->
<!-- =================================================================================== -->
<robot name="human_arm">
  <!--Gazebo link
    <link name="world"/>
    <joint name="joint_world_platform" type="fixed">
        <parent link="world"/>
        <child link="platform"/>
    </joint>-->
  <!--Human arm platform

    <link name="platform">
        <visual>
            <origin xyz="0 0 1"/>
            <geometry>
                <cylinder length="2." radius="1.25"/>
            </geometry>
        </visual>
        <collision>
            <surface>
                <contact>
                    <collide_bitmask>0x01</collide_bitmask>
                </contact>
            </surface>
            <origin xyz="0 0 1"/>
            <geometry>
                <cylinder length="2." radius="1.25"/>
            </geometry>
        </collision>
        <inertial>
            <origin xyz="0 0 1"/>
            <mass value="1000"/>
                <inertia ixx="${1/12 * 1000 * (3*pow(1.25,2) + pow(2,2))}"  ixy="0"  ixz="0" iyy="${1/12 * 1000 * (3*pow(1.25,2) + pow(2,2))}"
                 iyz="0" izz="${1/2 * 1000 * pow(1.25,2)}" />
        </inertial>
    </link>-->
  <link name="base_link">
    <visual>
      <origin rpy="-0.0 -1.57079632679 0.0" xyz="-0.005 0.0 -0.0"/>
      <geometry>
        <cylinder length="0.01" radius="0.005"/>
      </geometry>
    </visual>
    <collision>
      <origin rpy="-0.0 -1.57079632679 0.0" xyz="-0.005 0.0 -0.0"/>
      <geometry>
        <cylinder length="0.01" radius="0.005"/>
      </geometry>
    </collision>
    <inertial>
      <origin rpy="-0.0 -1.57079632679 0.0" xyz="-0.005 0.0 -0.0"/>
      <mass value="0.145298660229"/>
      <inertia ixx="2.118938795e-06" ixy="0" ixz="0" iyy="2.118938795e-06" iyz="0" izz="1.81623325286e-06"/>
    </inertial>
  </link>
  <link name="Scaphant">
    <visual>
      <origin rpy="-0.0 -1.57079632679 0.0" xyz="-0.005 0.0 -0.0"/>
      <geometry>
        <cylinder length="0.01" radius="0.005"/>
      </geometry>
    </visual>
    <collision>
      <origin rpy="-0.0 -1.57079632679 0.0" xyz="-0.005 0.0 -0.0"/>
      <geometry>
        <cylinder length="0.01" radius="0.005"/>
      </geometry>
    </collision>
    <inertial>
      <origin rpy="-0.0 -1.57079632679 0.0" xyz="-0.005 0.0 -0.0"/>
      <mass value="0.145298660229"/>
      <inertia ixx="2.118938795e-06" ixy="0" ixz="0" iyy="2.118938795e-06" iyz="0" izz="1.81623325286e-06"/>
    </inertial>
  </link>
  <link name="Humphant">
    <visual>
      <origin rpy="-0.0 -1.57079632679 0.0" xyz="-0.005 0.0 -0.0"/>
      <geometry>
        <cylinder length="0.01" radius="0.005"/>
      </geometry>
    </visual>
    <collision>
      <origin rpy="-0.0 -1.57079632679 0.0" xyz="-0.005 0.0 -0.0"/>
      <geometry>
        <cylinder length="0.01" radius="0.005"/>
      </geometry>
    </collision>
    <inertial>
      <origin rpy="-0.0 -1.57079632679 0.0" xyz="-0.005 0.0 -0.0"/>
      <mass value="0.145298660229"/>
      <inertia ixx="2.118938795e-06" ixy="0" ixz="0" iyy="2.118938795e-06" iyz="0" izz="1.81623325286e-06"/>
    </inertial>
  </link>
  <link name="Humphant1">
    <visual>
      <origin rpy="-0.0 -1.57079632679 0.0" xyz="-0.005 0.0 -0.0"/>
      <geometry>
        <cylinder length="0.01" radius="0.005"/>
      </geometry>
    </visual>
    <collision>
      <origin rpy="-0.0 -1.57079632679 0.0" xyz="-0.005 0.0 -0.0"/>
      <geometry>
        <cylinder length="0.01" radius="0.005"/>
      </geometry>
    </collision>
    <inertial>
      <origin rpy="-0.0 -1.57079632679 0.0" xyz="-0.005 0.0 -0.0"/>
      <mass value="0.145298660229"/>
      <inertia ixx="2.118938795e-06" ixy="0" ixz="0" iyy="2.118938795e-06" iyz="0" izz="1.81623325286e-06"/>
    </inertial>
  </link>
  <!-- Real links-->
  <link name="Humerus">
    <visual>
      <origin rpy="0.0 -0.0 0.0" xyz="-0.0 0.0 0.1452"/>
      <geometry>
        <cylinder length="0.2904" radius="0.01"/>
      </geometry>
    </visual>
    <collision>
      <origin rpy="0.0 -0.0 0.0" xyz="-0.0 0.0 0.1452"/>
      <geometry>
        <cylinder length="0.2904" radius="0.01"/>
      </geometry>
    </collision>
    <inertial>
      <origin rpy="0.0 -0.0 0.0" xyz="-0.0 0.0 0.1452"/>
      <mass value="16.8778923721"/>
      <inertia ixx="0.119034373975" ixy="0" ixz="0" iyy="0.119034373975" iyz="0" izz="0.000843894618607"/>
    </inertial>
  </link>
  <link name="Ulna">
    <visual>
      <origin rpy="3.14159265359 -0.00483242991587 -3.14159265359" xyz="-0.00305 -3.7351727374e-19 -0.00385"/>
      <geometry>
        <cylinder length="0.00982344135219" radius="0.01"/>
      </geometry>
    </visual>
    <collision>
      <origin rpy="3.14159265359 -0.00483242991587 -3.14159265359" xyz="-0.00305 -3.7351727374e-19 -0.00385"/>
      <geometry>
        <cylinder length="0.00982344135219" radius="0.01"/>
      </geometry>
    </collision>
    <inertial>
      <origin rpy="3.14159265359 -0.00483242991587 -3.14159265359" xyz="-0.00305 -3.7351727374e-19 -0.00385"/>
      <mass value="0.570933146923"/>
      <inertia ixx="1.88645827296e-05" ixy="0" ixz="0" iyy="1.88645827296e-05" iyz="0" izz="2.85466573461e-05"/>
    </inertial>
  </link>
  <link name="Radius">
    <visual>
      <origin rpy="0.0 -0.0 0.0" xyz="0.0 0.0 0.12875"/>
      <geometry>
        <cylinder length="0.2575" radius="0.01"/>
      </geometry>
    </visual>
    <collision>
      <origin rpy="0.0 -0.0 0.0" xyz="0.0 0.0 0.12875"/>
      <geometry>
        <cylinder length="0.2575" radius="0.01"/>
      </geometry>
    </collision>
    <inertial>
      <origin rpy="0.0 -0.0 0.0" xyz="0.0 0.0 0.12875"/>
      <mass value="14.9657620035"/>
      <inertia ixx="0.0830677737873" ixy="0" ixz="0" iyy="0.0830677737873" iyz="0" izz="0.000748288100177"/>
    </inertial>
  </link>
  <link name="Z6">
    <visual>
      <origin rpy="0.00370247507156 -0.00073982569831 -1.32797627839e-06" xyz="-0.00102871725727 -0.00514822695737 0.0146"/>
      <geometry>
        <cylinder length="0.0310304688975" radius="0.01"/>
      </geometry>
    </visual>
    <collision>
      <origin rpy="0.00370247507156 -0.00073982569831 -1.32797627839e-06" xyz="-0.00102871725727 -0.00514822695737 0.0146"/>
      <geometry>
        <cylinder length="0.0310304688975" radius="0.01"/>
      </geometry>
    </collision>
    <inertial>
      <origin rpy="0.00370247507156 -0.00073982569831 -1.32797627839e-06" xyz="-0.00102871725727 -0.00514822695737 0.0146"/>
      <mass value="1.80347422283"/>
      <inertia ixx="0.000189799130106" ixy="0" ixz="0" iyy="0.000189799130106" iyz="0" izz="9.01737111415e-05"/>
    </inertial>
  </link>
  <link name="Hand">
    <visual>
      <origin rpy="-1.57079632679 6.12323399574e-17 -6.12323399574e-17" xyz="2.44929359829e-18 0.04 -0.0"/>
      <geometry>
        <cylinder length="0.08" radius="0.01"/>
      </geometry>
    </visual>
    <collision>
      <origin rpy="-1.57079632679 6.12323399574e-17 -6.12323399574e-17" xyz="2.44929359829e-18 0.04 -0.0"/>
      <geometry>
        <cylinder length="0.08" radius="0.01"/>
      </geometry>
    </collision>
    <inertial>
      <origin rpy="-1.57079632679 6.12323399574e-17 -6.12323399574e-17" xyz="2.44929359829e-18 0.04 -0.0"/>
      <mass value="4.64955712731"/>
      <inertia ixx="0.00259600272942" ixy="0" ixz="0" iyy="0.00259600272942" iyz="0" izz="0.000232477856366"/>
    </inertial>
  </link>
  <!--Added pseudo link properties-->
  <link name="Lunate">
    <visual>
      <origin rpy="-1.57079632679 -1.33168621927 1.33168621927" xyz="-0.00485774559999 0.00118419073033 -0.0"/>
      <geometry>
        <cylinder length="0.01" radius="0.005"/>
      </geometry>
    </visual>
    <collision>
      <origin rpy="-1.57079632679 -1.33168621927 1.33168621927" xyz="-0.00485774559999 0.00118419073033 -0.0"/>
      <geometry>
        <cylinder length="0.01" radius="0.005"/>
      </geometry>
    </collision>
    <inertial>
      <origin rpy="-1.57079632679 -1.33168621927 1.33168621927" xyz="-0.00485774559999 0.00118419073033 -0.0"/>
      <mass value="0.145298660229"/>
      <inertia ixx="2.118938795e-06" ixy="0" ixz="0" iyy="2.118938795e-06" iyz="0" izz="1.81623325286e-06"/>
    </inertial>
  </link>
  <!--Human arm platform joints

    <xacro:DH_joint parent="platform" child ="base_link" joint_t="fixed" d="2" a="-1.26">
        <axis xyz="0 0 0"/>
    </xacro:DH_joint>-->
  <joint name="joint_base_link_Scaphant" type="fixed">
    <parent link="base_link"/>
    <child link="Scaphant"/>
    <origin rpy="0.0 -0.0 1.57079632679" xyz="0.0 -0.0 0.0"/>
  </joint>
  <joint name="joint_Scaphant_Humphant" type="revolute">
    <parent link="Scaphant"/>
    <child link="Humphant"/>
    <origin rpy="0.0 -0.0 0.0" xyz="0.0 -0.0 0.0"/>
    <axis xyz="0 0 1"/>
    <limit effort="1000.0" lower="-1.57079632679" upper="2.26892802759" velocity="0.5"/>
  </joint>
  <transmission name="Scaphant_trans">
    <type>transmission_interface/SimpleTransmission</type>
    <joint name="joint_Scaphant_Humphant">
      <hardwareInterface>hardware_interface/EffortJointInterface</hardwareInterface>
    </joint>
    <actuator name="Scaphant_motor">
      <hardwareInterface>hardware_interface/EffortJointInterface</hardwareInterface>
    </actuator>
  </transmission>
  <joint name="joint_Humphant_Humphant1" type="revolute">
    <parent link="Humphant"/>
    <child link="Humphant1"/>
    <origin rpy="1.57079632679 -0.0 0.0" xyz="0.0 -0.0 0.0"/>
    <axis xyz="0 0 1"/>
    <limit effort="1000.0" lower="0.0" upper="3.14159265359" velocity="0.5"/>
  </joint>
  <transmission name="Humphant_trans">
    <type>transmission_interface/SimpleTransmission</type>
    <joint name="joint_Humphant_Humphant1">
      <hardwareInterface>hardware_interface/EffortJointInterface</hardwareInterface>
    </joint>
    <actuator name="Humphant_motor">
      <hardwareInterface>hardware_interface/EffortJointInterface</hardwareInterface>
    </actuator>
  </transmission>
  <joint name="joint_Humphant1_Humerus" type="revolute">
    <parent link="Humphant1"/>
    <child link="Humerus"/>
    <origin rpy="-0.785398163397 -1.57079632679 -0.785398163397" xyz="0.0 -0.2904 -1.77818715236e-17"/>
    <axis xyz="0 0 1"/>
    <limit effort="1000.0" lower="-3.83972435439" upper="1.91986217719" velocity="0.5"/>
  </joint>
  <transmission name="Humphant1_trans">
    <type>transmission_interface/SimpleTransmission</type>
    <joint name="joint_Humphant1_Humerus">
      <hardwareInterface>hardware_interface/EffortJointInterface</hardwareInterface>
    </joint>
    <actuator name="Humphant1_motor">
      <hardwareInterface>hardware_interface/EffortJointInterface</hardwareInterface>
    </actuator>
  </transmission>
  <joint name="joint_Humerus_Ulna" type="revolute">
    <parent link="Humerus"/>
    <child link="Ulna"/>
    <origin rpy="1.57079632679 1.22464679915e-16 3.14159265359" xyz="-0.0061 0.0077 4.71489017672e-19"/>
    <axis xyz="0 0 1"/>
    <limit effort="1000.0" lower="0.0" upper="2.26892802759" velocity="0.5"/>
  </joint>
  <transmission name="Humerus_trans">
    <type>transmission_interface/SimpleTransmission</type>
    <joint name="joint_Humerus_Ulna">
      <hardwareInterface>hardware_interface/EffortJointInterface</hardwareInterface>
    </joint>
    <actuator name="Humerus_motor">
      <hardwareInterface>hardware_interface/EffortJointInterface</hardwareInterface>
    </actuator>
  </transmission>
  <joint name="joint_Ulna_Radius" type="revolute">
    <parent link="Ulna"/>
    <child link="Radius"/>
    <origin rpy="1.57079632679 -0.973893722613 -3.14159265359" xyz="0.0 -0.2575 -1.5767327539e-17"/>
    <axis xyz="0 0 1"/>
    <limit effort="1000.0" lower="-1.57079632679" upper="1.57079632679" velocity="0.5"/>
  </joint>
  <transmission name="Ulna_trans">
    <type>transmission_interface/SimpleTransmission</type>
    <joint name="joint_Ulna_Radius">
      <hardwareInterface>hardware_interface/EffortJointInterface</hardwareInterface>
    </joint>
    <actuator name="Ulna_motor">
      <hardwareInterface>hardware_interface/EffortJointInterface</hardwareInterface>
    </actuator>
  </transmission>
  <joint name="joint_Radius_Z6" type="revolute">
    <parent link="Radius"/>
    <child link="Z6"/>
    <origin rpy="-2.18090776315 -1.33165554748 -2.54497002525" xyz="-0.0105 0.0289298369418 0.00396289471508"/>
    <axis xyz="0 0 1"/>
    <limit effort="1000.0" lower="-0.174532925199" upper="0.436332312999" velocity="0.5"/>
  </joint>
  <transmission name="Radius_trans">
    <type>transmission_interface/SimpleTransmission</type>
    <joint name="joint_Radius_Z6">
      <hardwareInterface>hardware_interface/EffortJointInterface</hardwareInterface>
    </joint>
    <actuator name="Radius_motor">
      <hardwareInterface>hardware_interface/EffortJointInterface</hardwareInterface>
    </actuator>
  </transmission>
  <joint name="joint_Z6_Lunate" type="revolute">
    <parent link="Z6"/>
    <child link="Lunate"/>
    <origin rpy="-2.54422044057 0.13626609681 -0.197095295237" xyz="0.0 0.0 -0.0"/>
    <axis xyz="0 0 1"/>
    <limit effort="1000.0" lower="-0.610865238198" upper="0.610865238198" velocity="0.5"/>
  </joint>
  <transmission name="Z6_trans">
    <type>transmission_interface/SimpleTransmission</type>
    <joint name="joint_Z6_Lunate">
      <hardwareInterface>hardware_interface/EffortJointInterface</hardwareInterface>
    </joint>
    <actuator name="Z6_motor">
      <hardwareInterface>hardware_interface/EffortJointInterface</hardwareInterface>
    </actuator>
  </transmission>
  <joint name="joint_Lunate_Hand" type="fixed">
    <parent link="Lunate"/>
    <child link="Hand"/>
    <origin rpy="-0.785398163397 -1.57079632679 -0.785398163397" xyz="-0.08 0.0 0.0"/>
  </joint>
  <!-- ros_control plugin -->
  <gazebo>
    <plugin filename="libgazebo_ros_control.so" name="gazebo_ros_control">
        </plugin>
  </gazebo>
  <!-- 
    <gazebo reference="platform">
        <selfCollide>0</selfCollide>
    </gazebo>
-->
  <gazebo reference="base_link">
    <gravity>0</gravity>
    <selfCollide>0</selfCollide>
    <material>Gazebo/Orange</material>
    <collision>
      <surface>
        <contact>
          <collide_bitmask>0x01</collide_bitmask>
        </contact>
      </surface>
    </collision>
  </gazebo>
  <gazebo reference="Scaphant">
    <gravity>0</gravity>
    <selfCollide>0</selfCollide>
    <material>Gazebo/Orange</material>
    <collision>
      <surface>
        <contact>
          <collide_bitmask>0x01</collide_bitmask>
        </contact>
      </surface>
    </collision>
  </gazebo>
  <gazebo reference="Humphant">
    <gravity>0</gravity>
    <selfCollide>0</selfCollide>
    <material>Gazebo/Orange</material>
    <collision>
      <surface>
        <contact>
          <collide_bitmask>0x01</collide_bitmask>
        </contact>
      </surface>
    </collision>
  </gazebo>
  <gazebo reference="Humphant1">
    <gravity>0</gravity>
    <selfCollide>0</selfCollide>
    <material>Gazebo/Orange</material>
    <collision>
      <surface>
        <contact>
          <collide_bitmask>0x01</collide_bitmask>
        </contact>
      </surface>
    </collision>
  </gazebo>
  <gazebo reference="Humerus">
    <gravity>0</gravity>
    <selfCollide>0</selfCollide>
    <material>Gazebo/Orange</material>
    <collision>
      <surface>
        <contact>
          <collide_bitmask>0x01</collide_bitmask>
        </contact>
      </surface>
    </collision>
  </gazebo>
  <gazebo reference="Ulna">
    <gravity>0</gravity>
    <selfCollide>0</selfCollide>
    <material>Gazebo/Orange</material>
    <collision>
      <surface>
        <contact>
          <collide_bitmask>0x01</collide_bitmask>
        </contact>
      </surface>
    </collision>
  </gazebo>
  <gazebo reference="Radius">
    <gravity>0</gravity>
    <selfCollide>0</selfCollide>
    <material>Gazebo/Orange</material>
    <collision>
      <surface>
        <contact>
          <collide_bitmask>0x01</collide_bitmask>
        </contact>
      </surface>
    </collision>
  </gazebo>
  <gazebo reference="Z6">
    <gravity>0</gravity>
    <selfCollide>0</selfCollide>
    <material>Gazebo/Orange</material>
    <collision>
      <surface>
        <contact>
          <collide_bitmask>0x01</collide_bitmask>
        </contact>
      </surface>
    </collision>
  </gazebo>
  <gazebo reference="Lunate">
    <gravity>0</gravity>
    <selfCollide>0</selfCollide>
    <material>Gazebo/Orange</material>
    <collision>
      <surface>
        <contact>
          <collide_bitmask>0x01</collide_bitmask>
        </contact>
      </surface>
    </collision>
  </gazebo>
  <gazebo reference="Hand">
    <gravity>0</gravity>
    <selfCollide>0</selfCollide>
    <material>Gazebo/Orange</material>
    <collision>
      <surface>
        <contact>
          <collide_bitmask>0x01</collide_bitmask>
        </contact>
      </surface>
    </collision>
  </gazebo>
  <gazebo reference="joint_platform_base_link">
    <implicitSpringDamper>True</implicitSpringDamper>
  </gazebo>
  <gazebo reference="joint_base_link_Scaphant">
    <implicitSpringDamper>True</implicitSpringDamper>
  </gazebo>
  <gazebo reference="joint_Scaphant_Humphant">
    <implicitSpringDamper>True</implicitSpringDamper>
  </gazebo>
  <gazebo reference="joint_Humphant_Humphant1">
    <implicitSpringDamper>True</implicitSpringDamper>
  </gazebo>
  <gazebo reference="joint_Humphant1_Humerus">
    <implicitSpringDamper>True</implicitSpringDamper>
  </gazebo>
  <gazebo reference="joint_Humerus_Ulna">
    <implicitSpringDamper>True</implicitSpringDamper>
  </gazebo>
  <gazebo reference="joint_Ulna_Radius">
    <implicitSpringDamper>True</implicitSpringDamper>
  </gazebo>
  <gazebo reference="joint_Radius_Z6">
    <implicitSpringDamper>True</implicitSpringDamper>
  </gazebo>
  <gazebo reference="joint_Z6_Lunate">
    <implicitSpringDamper>True</implicitSpringDamper>
  </gazebo>
  <gazebo reference="joint_Lunate_Hand">
    <implicitSpringDamper>True</implicitSpringDamper>
  </gazebo>
</robot>

