<?xml version="1.0" encoding="utf-8"?>
<!-- =================================================================================== -->
<!-- |    This document was autogenerated by xacro from human_arm_description.urdf.xacro | -->
<!-- |    EDITING THIS FILE BY HAND IS NOT RECOMMENDED                                 | -->
<!-- =================================================================================== -->
<robot name="human_arm">
  <joint name="joint_base_link_Scaphant" type="fixed">
    <parent link="base_link"/>
    <child link="Scaphant"/>
    <origin rpy="0.0 -0.0 1.57079632679" xyz="0.001 -0.0 0.001"/>
  </joint>
  <link name="base_link">
    <visual>
      <geometry>
        <cylinder length="0.00141421356237" radius="0.001"/>
      </geometry>
      <!--Maybe make origin into some sort of variable? Used 3 times-->
      <origin rpy="0.0 0.000999999666667 0.0" xyz="0.0005 -0.0 0.0005"/>
    </visual>
    <collsion>
      <geometry>
        <cylinder length="0.00141421356237" radius="0.001"/>
      </geometry>
      <origin rpy="0.0 0.000999999666667 0.0" xyz="0.0005 -0.0 0.0005"/>
    </collsion>
    <inertial>
      <mass value="8.21933343559e-06"/>
      <inertia ixx="1.36988890593e-12" ixy="0.0" ixz="0.0" iyy="0" iyz="0.0" izz="1.36988890593e-12"/>
    </inertial>
  </link>
  <joint name="joint_Scaphant_Humphant" type="revolute">
    <parent link="Scaphant"/>
    <child link="Humphant"/>
    <origin rpy="0.0 -0.0 0.0" xyz="0.001 -0.0 0.001"/>
    <axis xyz="0 0 1"/>
    <limit effort="1000.0" lower="0" upper="6.28318530718" velocity="0.5"/>
  </joint>
  <link name="Scaphant">
    <visual>
      <geometry>
        <cylinder length="0.00141421356237" radius="0.001"/>
      </geometry>
      <!--Maybe make origin into some sort of variable? Used 3 times-->
      <origin rpy="0.0 0.000999999666667 0.0" xyz="0.0005 -0.0 0.0005"/>
    </visual>
    <collsion>
      <geometry>
        <cylinder length="0.00141421356237" radius="0.001"/>
      </geometry>
      <origin rpy="0.0 0.000999999666667 0.0" xyz="0.0005 -0.0 0.0005"/>
    </collsion>
    <inertial>
      <mass value="8.21933343559e-06"/>
      <inertia ixx="1.36988890593e-12" ixy="0.0" ixz="0.0" iyy="0" iyz="0.0" izz="1.36988890593e-12"/>
    </inertial>
  </link>
  <joint name="joint_Humphant_Humphant1" type="revolute">
    <parent link="Humphant"/>
    <child link="Humphant1"/>
    <origin rpy="1.57079632679 -0.0 0.0" xyz="0.001 -0.001 6.12323399574e-20"/>
    <axis xyz="0 0 1"/>
    <limit effort="1000.0" lower="0" upper="6.28318530718" velocity="0.5"/>
  </joint>
  <link name="Humphant">
    <visual>
      <geometry>
        <cylinder length="0.00141421356237" radius="0.001"/>
      </geometry>
      <!--Maybe make origin into some sort of variable? Used 3 times-->
      <origin rpy="1.57079632679 0.785398163397 0.785398163367" xyz="0.0005 -0.0005 3.06161699787e-20"/>
    </visual>
    <collsion>
      <geometry>
        <cylinder length="0.00141421356237" radius="0.001"/>
      </geometry>
      <origin rpy="1.57079632679 0.785398163397 0.785398163367" xyz="0.0005 -0.0005 3.06161699787e-20"/>
    </collsion>
    <inertial>
      <mass value="8.21933343559e-06"/>
      <inertia ixx="1.36988890593e-12" ixy="0.0" ixz="0.0" iyy="0" iyz="0.0" izz="1.36988890593e-12"/>
    </inertial>
  </link>
  <joint name="joint_Humphant1_Humerus" type="revolute">
    <parent link="Humphant1"/>
    <child link="Humerus"/>
    <origin rpy="-0.785398163397 -1.57079632679 -0.785398163397" xyz="0.0 -0.2904 -1.77818715236e-17"/>
    <axis xyz="0 0 1"/>
    <limit effort="1000.0" lower="0" upper="6.28318530718" velocity="0.5"/>
  </joint>
  <link name="Humphant1">
    <visual>
      <geometry>
        <cylinder length="0.2904" radius="0.01"/>
      </geometry>
      <!--Maybe make origin into some sort of variable? Used 3 times-->
      <origin rpy="1.57079632679 0.0 0.0" xyz="0.0 -0.1452 -8.89093576181e-18"/>
    </visual>
    <collsion>
      <geometry>
        <cylinder length="0.2904" radius="0.01"/>
      </geometry>
      <origin rpy="1.57079632679 0.0 0.0" xyz="0.0 -0.1452 -8.89093576181e-18"/>
    </collsion>
    <inertial>
      <mass value="0.168778923721"/>
      <inertia ixx="0.00118612426666" ixy="0.0" ixz="0.0" iyy="0" iyz="0.0" izz="0.00118612426666"/>
    </inertial>
  </link>
  <joint name="joint_Humerus_Ulna" type="revolute">
    <parent link="Humerus"/>
    <child link="Ulna"/>
    <origin rpy="1.57079632679 1.22464679915e-16 3.14159265359" xyz="-0.0061 0.0077 4.71489017672e-19"/>
    <axis xyz="0 0 1"/>
    <limit effort="1000.0" lower="0" upper="6.28318530718" velocity="0.5"/>
  </joint>
  <link name="Humerus">
    <visual>
      <geometry>
        <cylinder length="0.00982344135219" radius="0.01"/>
      </geometry>
      <!--Maybe make origin into some sort of variable? Used 3 times-->
      <origin rpy="-1.57079632679 -0.669971503031 0.66997150303" xyz="-0.00305 0.00385 2.35744508836e-19"/>
    </visual>
    <collsion>
      <geometry>
        <cylinder length="0.00982344135219" radius="0.01"/>
      </geometry>
      <origin rpy="-1.57079632679 -0.669971503031 0.66997150303" xyz="-0.00305 0.00385 2.35744508836e-19"/>
    </collsion>
    <inertial>
      <mass value="0.00570933146923"/>
      <inertia ixx="4.59125405651e-08" ixy="0.0" ixz="0.0" iyy="0" iyz="0.0" izz="4.59125405651e-08"/>
    </inertial>
  </link>
  <joint name="joint_Ulna_Radius" type="revolute">
    <parent link="Ulna"/>
    <child link="Radius"/>
    <origin rpy="1.57079632679 -0.973893722613 -3.14159265359" xyz="0.0 -0.2575 -1.5767327539e-17"/>
    <axis xyz="0 0 1"/>
    <limit effort="1000.0" lower="0" upper="6.28318530718" velocity="0.5"/>
  </joint>
  <link name="Ulna">
    <visual>
      <geometry>
        <cylinder length="0.2575" radius="0.01"/>
      </geometry>
      <!--Maybe make origin into some sort of variable? Used 3 times-->
      <origin rpy="1.57079632679 0.0 0.0" xyz="0.0 -0.12875 -7.88366376951e-18"/>
    </visual>
    <collsion>
      <geometry>
        <cylinder length="0.2575" radius="0.01"/>
      </geometry>
      <origin rpy="1.57079632679 0.0 0.0" xyz="0.0 -0.12875 -7.88366376951e-18"/>
    </collsion>
    <inertial>
      <mass value="0.149657620035"/>
      <inertia ixx="0.000826936297373" ixy="0.0" ixz="0.0" iyy="0" iyz="0.0" izz="0.000826936297373"/>
    </inertial>
  </link>
  <joint name="joint_Radius_Z6" type="revolute">
    <parent link="Radius"/>
    <child link="Z6"/>
    <origin rpy="-2.18090776315 -1.33165554748 -2.54497002525" xyz="0.0105 0.0289298369418 0.00396289471508"/>
    <axis xyz="0 0 1"/>
    <limit effort="1000.0" lower="0" upper="6.28318530718" velocity="0.5"/>
  </joint>
  <link name="Radius">
    <visual>
      <geometry>
        <cylinder length="0.0310304688975" radius="0.01"/>
      </geometry>
      <!--Maybe make origin into some sort of variable? Used 3 times-->
      <origin rpy="-0.221003216536 0.0793938657583 -0.00206298420584" xyz="0.00525 0.0144649184709 0.00198144735754"/>
    </visual>
    <collsion>
      <geometry>
        <cylinder length="0.0310304688975" radius="0.01"/>
      </geometry>
      <origin rpy="-0.221003216536 0.0793938657583 -0.00206298420584" xyz="0.00525 0.0144649184709 0.00198144735754"/>
    </collsion>
    <inertial>
      <mass value="0.0180347422283"/>
      <inertia ixx="1.44712274535e-06" ixy="0.0" ixz="0.0" iyy="0" iyz="0.0" izz="1.44712274535e-06"/>
    </inertial>
  </link>
  <joint name="joint_Z6_Lunate" type="revolute">
    <parent link="Z6"/>
    <child link="Lunate"/>
    <origin rpy="-2.54422044057 0.13626609681 -0.197095295237" xyz="0.001 0.000573576436351 -0.000819152044289"/>
    <axis xyz="0 0 1"/>
    <limit effort="1000.0" lower="0" upper="6.28318530718" velocity="0.5"/>
  </joint>
  <link name="Z6">
    <visual>
      <geometry>
        <cylinder length="0.00141421356237" radius="0.001"/>
      </geometry>
      <!--Maybe make origin into some sort of variable? Used 3 times-->
      <origin rpy="-3.14078544173 0.00140732984317 -3.14159108977" xyz="0.0005 0.000286788218176 -0.000409576022144"/>
    </visual>
    <collsion>
      <geometry>
        <cylinder length="0.00141421356237" radius="0.001"/>
      </geometry>
      <origin rpy="-3.14078544173 0.00140732984317 -3.14159108977" xyz="0.0005 0.000286788218176 -0.000409576022144"/>
    </collsion>
    <inertial>
      <mass value="8.21933343559e-06"/>
      <inertia ixx="1.36988890593e-12" ixy="0.0" ixz="0.0" iyy="0" iyz="0.0" izz="1.36988890593e-12"/>
    </inertial>
  </link>
  <joint name="joint_Lunate_Hand" type="fixed">
    <parent link="Lunate"/>
    <child link="Hand"/>
    <origin rpy="-0.785398163397 -1.57079632679 -0.785398163397" xyz="0.001 0.001 6.12323399574e-20"/>
  </joint>
  <link name="Lunate">
    <visual>
      <geometry>
        <cylinder length="0.00141421356237" radius="0.001"/>
      </geometry>
      <!--Maybe make origin into some sort of variable? Used 3 times-->
      <origin rpy="-1.57079632679 0.785398163397 -0.785398163367" xyz="0.0005 0.0005 3.06161699787e-20"/>
    </visual>
    <collsion>
      <geometry>
        <cylinder length="0.00141421356237" radius="0.001"/>
      </geometry>
      <origin rpy="-1.57079632679 0.785398163397 -0.785398163367" xyz="0.0005 0.0005 3.06161699787e-20"/>
    </collsion>
    <inertial>
      <mass value="8.21933343559e-06"/>
      <inertia ixx="1.36988890593e-12" ixy="0.0" ixz="0.0" iyy="0" iyz="0.0" izz="1.36988890593e-12"/>
    </inertial>
  </link>
  <link name="Hand">
  </link>
  <!--<gazebo>
    <plugin name="gazebo_ros_control" filename="libgazebo_ros_control.so">
      <robotNamespace>/</robotNamespace>
    </plugin>
  </gazebo>-->
</robot>

